<sdf version='1.10'>
  <world name='myworld'>
    <physics name='1ms' type='ignored'>
      <max_step_size>0.001</max_step_size>
      <real_time_factor>1</real_time_factor>
      <real_time_update_rate>1000</real_time_update_rate>
    </physics>
    <plugin name='gz::sim::systems::Physics' filename='gz-sim-physics-system'/>
    <plugin name='gz::sim::systems::UserCommands' filename='gz-sim-user-commands-system'/>
    <plugin name='gz::sim::systems::SceneBroadcaster' filename='gz-sim-scene-broadcaster-system'/>
    <plugin name='gz::sim::systems::Sensors' filename='gz-sim-sensors-system'>
      <render_engine>ogre2</render_engine>
    </plugin>
    <plugin name='gz::sim::systems::Contact' filename='gz-sim-contact-system'/>
    <plugin name='gz::sim::systems::Imu' filename='gz-sim-imu-system'/>
    <plugin name='gz::sim::systems::AirPressure' filename='gz-sim-air-pressure-system'/>
    <plugin name='gz::sim::systems::AirSpeed' filename='gz-sim-air-speed-system'/>
    <plugin name='gz::sim::systems::ApplyLinkWrench' filename='gz-sim-apply-link-wrench-system'/>
    <plugin name='gz::sim::systems::NavSat' filename='gz-sim-navsat-system'/>
    <plugin name='gz::sim::systems::Magnetometer' filename='gz-sim-magnetometer-system'/>
    <gravity>0 0 -9.8000000000000007</gravity>
    <magnetic_field>5.5644999999999998e-06 2.2875799999999999e-05 -4.2388400000000002e-05</magnetic_field>
    <atmosphere type='adiabatic'/>
    <scene>
      <ambient>0.400000006 0.400000006 0.400000006 1</ambient>
      <background>0.699999988 0.699999988 0.699999988 1</background>
      <shadows>true</shadows>
    </scene>
    <spherical_coordinates>
      <surface_model>EARTH_WGS84</surface_model>
      <world_frame_orientation>ENU</world_frame_orientation>
      <latitude_deg>47.397971057728974</latitude_deg>
      <longitude_deg>8.5461637398001464</longitude_deg>
      <elevation>0</elevation>
      <heading_deg>0</heading_deg>
    </spherical_coordinates>
    <model name='ground_plane'>
      <static>true</static>
      <link name='link'>
        <collision name='collision'>
          <geometry>
            <plane>
              <normal>0 0 1</normal>
              <size>500 500</size>
            </plane>
          </geometry>
          <surface>
            <friction>
              <ode>
                <mu>1</mu>
                <mu2>1</mu2>
              </ode>
            </friction>
            <bounce/>
            <contact/>
          </surface>
        </collision>
        <visual name='visual'>
          <geometry>
            <plane>
              <normal>0 0 1</normal>
              <size>500 500</size>
            </plane>
          </geometry>
          <material>
            <ambient>0.5 0.600000024 0.400000006 1</ambient>
            <diffuse>0.5 0.600000024 0.400000006 1</diffuse>
            <specular>0.100000001 0.100000001 0.100000001 1</specular>
          </material>
        </visual>
        <pose>0 0 0 0 0 0</pose>
        <inertial>
          <pose>0 0 0 0 0 0</pose>
          <mass>1</mass>
          <inertia>
            <ixx>1</ixx>
            <ixy>0</ixy>
            <ixz>0</ixz>
            <iyy>1</iyy>
            <iyz>0</iyz>
            <izz>1</izz>
          </inertia>
        </inertial>
        <enable_wind>false</enable_wind>
      </link>
      <pose>0 0 0 0 0 0</pose>
      <self_collide>false</self_collide>
    </model>
    <model name='tree_2'>
      <static>true</static>
      <link name='link'>
        <collision name='collision'>
          <geometry>
            <mesh>
              <uri>model://pine tree/meshes/pine_tree.dae</uri>
            </mesh>
          </geometry>
        </collision>
        <visual name='branch'>
          <geometry>
            <mesh>
              <uri>model://pine tree/meshes/pine_tree.dae</uri>
              <submesh>
                <name>Branch</name>
              </submesh>
            </mesh>
          </geometry>
          <material>
            <double_sided>true</double_sided>
            <diffuse>1 1 1 1</diffuse>
            <script>
              <uri>model://pine tree/materials/scripts/</uri>
              <uri>model://pine tree/materials/textures/</uri>
              <name>PineTree/Branch</name>
            </script>
            <pbr>
              <metal>
                <albedo_map>model://pine tree/materials/textures/branch_2_diffuse.png</albedo_map>
              </metal>
            </pbr>
          </material>
        </visual>
        <visual name='bark'>
          <geometry>
            <mesh>
              <uri>model://pine tree/meshes/pine_tree.dae</uri>
              <submesh>
                <name>Bark</name>
              </submesh>
            </mesh>
          </geometry>
          <material>
            <diffuse>1 1 1 1</diffuse>
            <script>
              <uri>model://pine tree/materials/scripts/</uri>
              <uri>model://pine tree/materials/textures/</uri>
              <name>PineTree/Bark</name>
            </script>
            <pbr>
              <metal>
                <albedo_map>model://pine tree/materials/textures/bark_diffuse.png</albedo_map>
              </metal>
            </pbr>
          </material>
        </visual>
        <pose>0 0 0 0 0 0</pose>
        <inertial>
          <pose>0 0 0 0 0 0</pose>
          <mass>1</mass>
          <inertia>
            <ixx>1</ixx>
            <ixy>0</ixy>
            <ixz>0</ixz>
            <iyy>1</iyy>
            <iyz>0</iyz>
            <izz>1</izz>
          </inertia>
        </inertial>
        <enable_wind>false</enable_wind>
      </link>
      <pose>-5 -7 0 0 0 0</pose>
      <self_collide>false</self_collide>
    </model>
    <model name='tree_3'>
      <static>true</static>
      <link name='link'>
        <collision name='collision'>
          <geometry>
            <mesh>
              <uri>model://oak tree/meshes/oak_tree.dae</uri>
            </mesh>
          </geometry>
        </collision>
        <visual name='branch'>
          <geometry>
            <mesh>
              <uri>model://oak tree/meshes/oak_tree.dae</uri>
              <submesh>
                <name>Branch</name>
              </submesh>
            </mesh>
          </geometry>
          <material>
            <double_sided>true</double_sided>
            <diffuse>1 1 1 1</diffuse>
            <script>
              <uri>model://oak tree/materials/scripts/</uri>
              <uri>model://oak tree/materials/textures/</uri>
              <name>OakTree/Branch</name>
            </script>
            <pbr>
              <metal>
                <albedo_map>model://oak tree/materials/textures/branch_diffuse.png</albedo_map>
              </metal>
            </pbr>
          </material>
        </visual>
        <visual name='bark'>
          <geometry>
            <mesh>
              <uri>model://oak tree/meshes/oak_tree.dae</uri>
              <submesh>
                <name>Bark</name>
              </submesh>
            </mesh>
          </geometry>
          <material>
            <diffuse>1 1 1 1</diffuse>
            <script>
              <uri>model://oak tree/materials/scripts/</uri>
              <uri>model://oak tree/materials/textures/</uri>
              <name>OakTree/Bark</name>
            </script>
            <pbr>
              <metal>
                <albedo_map>model://oak tree/materials/textures/bark_diffuse.png</albedo_map>
              </metal>
            </pbr>
          </material>
        </visual>
        <pose>0 0 0 0 0 0</pose>
        <inertial>
          <pose>0 0 0 0 0 0</pose>
          <mass>1</mass>
          <inertia>
            <ixx>1</ixx>
            <ixy>0</ixy>
            <ixz>0</ixz>
            <iyy>1</iyy>
            <iyz>0</iyz>
            <izz>1</izz>
          </inertia>
        </inertial>
        <enable_wind>false</enable_wind>
      </link>
      <pose>8 -6 0 0 0 0</pose>
      <self_collide>false</self_collide>
    </model>
    <model name='tree_4'>
      <static>true</static>
      <link name='link'>
        <collision name='collision'>
          <geometry>
            <mesh>
              <uri>model://pine tree/meshes/pine_tree.dae</uri>
            </mesh>
          </geometry>
        </collision>
        <visual name='branch'>
          <geometry>
            <mesh>
              <uri>model://pine tree/meshes/pine_tree.dae</uri>
              <submesh>
                <name>Branch</name>
              </submesh>
            </mesh>
          </geometry>
          <material>
            <double_sided>true</double_sided>
            <diffuse>1 1 1 1</diffuse>
            <script>
              <uri>model://pine tree/materials/scripts/</uri>
              <uri>model://pine tree/materials/textures/</uri>
              <name>PineTree/Branch</name>
            </script>
            <pbr>
              <metal>
                <albedo_map>model://pine tree/materials/textures/branch_2_diffuse.png</albedo_map>
              </metal>
            </pbr>
          </material>
        </visual>
        <visual name='bark'>
          <geometry>
            <mesh>
              <uri>model://pine tree/meshes/pine_tree.dae</uri>
              <submesh>
                <name>Bark</name>
              </submesh>
            </mesh>
          </geometry>
          <material>
            <diffuse>1 1 1 1</diffuse>
            <script>
              <uri>model://pine tree/materials/scripts/</uri>
              <uri>model://pine tree/materials/textures/</uri>
              <name>PineTree/Bark</name>
            </script>
            <pbr>
              <metal>
                <albedo_map>model://pine tree/materials/textures/bark_diffuse.png</albedo_map>
              </metal>
            </pbr>
          </material>
        </visual>
        <pose>0 0 0 0 0 0</pose>
        <inertial>
          <pose>0 0 0 0 0 0</pose>
          <mass>1</mass>
          <inertia>
            <ixx>1</ixx>
            <ixy>0</ixy>
            <ixz>0</ixz>
            <iyy>1</iyy>
            <iyz>0</iyz>
            <izz>1</izz>
          </inertia>
        </inertial>
        <enable_wind>false</enable_wind>
      </link>
      <pose>12 8 0 0 0 0</pose>
      <self_collide>false</self_collide>
    </model>
    <model name='vehicle_1'>
      <pose>5 -5 0 0 0 0</pose>
      <link name='chassis'>
        <inertial>
          <mass>1326</mass>
          <pose>0 -0.26600000000000001 0.47999999999999998 0 0 0</pose>
          <inertia>
            <ixx>2581.1335474000002</ixx>
            <ixy>0</ixy>
            <iyy>591.30846111999995</iyy>
            <ixz>0</ixz>
            <iyz>0</iyz>
            <izz>2681.9500862800001</izz>
          </inertia>
        </inertial>
        <visual name='chassis_visual'>
          <geometry>
            <mesh>
              <uri>model://prius hybrid/meshes/Hybrid.obj</uri>
              <scale>0.01 0.01 0.01</scale>
              <submesh>
                <name>Hybrid</name>
                <center>false</center>
              </submesh>
            </mesh>
          </geometry>
        </visual>
        <visual name='interior_visual'>
          <geometry>
            <mesh>
              <uri>model://prius hybrid/meshes/Hybrid.obj</uri>
              <scale>0.01 0.01 0.01</scale>
              <submesh>
                <name>Hybrid_Interior</name>
                <center>false</center>
              </submesh>
            </mesh>
          </geometry>
        </visual>
        <visual name='windows_visual'>
          <geometry>
            <mesh>
              <uri>model://prius hybrid/meshes/Hybrid.obj</uri>
              <scale>0.01 0.01 0.01</scale>
              <submesh>
                <name>Hybrid_Windows</name>
                <center>false</center>
              </submesh>
            </mesh>
          </geometry>
        </visual>
        <collision name='chassis'>
          <pose>0 0.050000000000000003 0.625 0 0 0</pose>
          <geometry>
            <box>
              <size>1.7525999999999999 2.1000000000000001 0.94999999999999996</size>
            </box>
          </geometry>
          <surface>
            <friction>
              <ode/>
            </friction>
            <bounce/>
            <contact/>
          </surface>
        </collision>
        <collision name='front_bumper'>
          <pose>0 -2 0.45848800000000001 0 0 0</pose>
          <geometry>
            <box>
              <size>1.3372820000000001 0.47999999999999998 0.56669099999999994</size>
            </box>
          </geometry>
          <surface>
            <friction>
              <ode/>
            </friction>
            <bounce/>
            <contact/>
          </surface>
        </collision>
        <collision name='hood'>
          <pose>0 -1.9008419999999999 0.67630500000000005 0.34124700000000019 0 0</pose>
          <geometry>
            <box>
              <size>1.5979680000000001 0.49310700000000002 0.26546799999999998</size>
            </box>
          </geometry>
          <surface>
            <friction>
              <ode/>
            </friction>
            <bounce/>
            <contact/>
          </surface>
        </collision>
        <collision name='windshield'>
          <pose>0 -0.87510500000000002 1.032268 0.335476 0 0</pose>
          <geometry>
            <box>
              <size>1.1683809999999999 1.654253 0.27234700000000001</size>
            </box>
          </geometry>
          <surface>
            <friction>
              <ode/>
            </friction>
            <bounce/>
            <contact/>
          </surface>
        </collision>
        <collision name='top_front'>
          <pose>0 0.16123599999999999 1.386042 0.13503000000000009 0 0</pose>
          <geometry>
            <box>
              <size>1.2791539999999999 0.62598799999999999 0.17186799999999999</size>
            </box>
          </geometry>
          <surface>
            <friction>
              <ode/>
            </friction>
            <bounce/>
            <contact/>
          </surface>
        </collision>
        <collision name='top_rear'>
          <pose>0 0.81769599999999998 1.360069 -0.068997000000000003 0 0</pose>
          <geometry>
            <box>
              <size>1.2851300000000001 0.77118900000000001 0.22655700000000001</size>
            </box>
          </geometry>
          <surface>
            <friction>
              <ode/>
            </friction>
            <bounce/>
            <contact/>
          </surface>
        </collision>
        <collision name='rear_window'>
          <pose>0 1.640531 1.1751259999999999 -0.26201699999999983 0 0</pose>
          <geometry>
            <box>
              <size>1.2678450000000001 1.116344 0.244286</size>
            </box>
          </geometry>
          <surface>
            <friction>
              <ode/>
            </friction>
            <bounce/>
            <contact/>
          </surface>
        </collision>
        <collision name='trunk'>
          <pose>0 1.637059 0.88817999999999997 0 0 0</pose>
          <geometry>
            <box>
              <size>1.7880640000000001 1.1389879999999999 0.48274600000000001</size>
            </box>
          </geometry>
          <surface>
            <friction>
              <ode/>
            </friction>
            <bounce/>
            <contact/>
          </surface>
        </collision>
        <collision name='back_bumper'>
          <pose>0 2.0544539999999998 0.57786999999999999 0 0 0</pose>
          <geometry>
            <box>
              <size>1.78165 0.51209300000000002 0.58142700000000003</size>
            </box>
          </geometry>
          <surface>
            <friction>
              <ode/>
            </friction>
            <bounce/>
            <contact/>
          </surface>
        </collision>
        <pose>0 0 0 0 0 0</pose>
        <enable_wind>false</enable_wind>
      </link>
      <link name='steering_wheel'>
        <pose>0.35773399999999977 -0.62786800000000031 0.98824299999999998 -1.3021010000000013 0 0</pose>
        <inertial>
          <mass>1</mass>
          <inertia>
            <ixx>0.14583299999999999</ixx>
            <ixy>0</ixy>
            <ixz>0</ixz>
            <iyy>0.14583299999999999</iyy>
            <iyz>0</iyz>
            <izz>0.125</izz>
          </inertia>
          <pose>0 0 0 0 0 0</pose>
        </inertial>
        <collision name='collision'>
          <geometry>
            <cylinder>
              <radius>0.178172</radius>
              <length>0.041845</length>
            </cylinder>
          </geometry>
          <surface>
            <contact>
              <ode>
                <min_depth>0.0030000000000000001</min_depth>
              </ode>
            </contact>
            <friction>
              <ode/>
            </friction>
            <bounce/>
          </surface>
        </collision>
        <visual name='visual'>
          <pose>0 0 0 1.302101 0 0</pose>
          <geometry>
            <mesh>
              <uri>model://prius hybrid/meshes/Hybrid.obj</uri>
              <scale>0.01 0.01 0.01</scale>
              <submesh>
                <name>Steering_Wheel</name>
                <center>true</center>
              </submesh>
            </mesh>
          </geometry>
        </visual>
        <enable_wind>false</enable_wind>
      </link>
      <link name='front_left_wheel'>
        <pose>0.75999999999999979 -1.4100000000000001 0.29999999999999999 0 0 0</pose>
        <inertial>
          <mass>11</mass>
          <inertia>
            <ixx>0.58631237999999997</ixx>
            <ixy>0</ixy>
            <iyy>0.33552910000000002</iyy>
            <ixz>0</ixz>
            <iyz>0</iyz>
            <izz>0.33552910000000002</izz>
          </inertia>
          <pose>0 0 0 0 0 0</pose>
        </inertial>
        <visual name='visual'>
          <pose>0.040000000000000001 0 0 0 0 0</pose>
          <geometry>
            <mesh>
              <uri>model://prius hybrid/meshes/Hybrid.obj</uri>
              <scale>0.01 0.01 0.01</scale>
              <submesh>
                <name>Wheel_Front_Left_</name>
                <center>true</center>
              </submesh>
            </mesh>
          </geometry>
        </visual>
        <collision name='collision'>
          <pose>0 0 0 0 1.5707963267948966 0</pose>
          <geometry>
            <sphere>
              <radius>0.31264999999999998</radius>
            </sphere>
          </geometry>
          <surface>
            <friction>
              <ode>
                <mu>0.90000000000000002</mu>
                <mu2>0.90000000000000002</mu2>
                <slip1>0</slip1>
                <slip2>0</slip2>
              </ode>
            </friction>
            <contact>
              <ode>
                <min_depth>0.001</min_depth>
                <kp>1000000000</kp>
              </ode>
            </contact>
            <bounce/>
          </surface>
        </collision>
        <enable_wind>false</enable_wind>
      </link>
      <link name='front_right_wheel'>
        <pose>-0.75999999999999979 -1.4100000000000001 0.29999999999999999 0 0 0</pose>
        <inertial>
          <mass>11</mass>
          <inertia>
            <ixx>0.58631237999999997</ixx>
            <ixy>0</ixy>
            <iyy>0.33552910000000002</iyy>
            <ixz>0</ixz>
            <iyz>0</iyz>
            <izz>0.33552910000000002</izz>
          </inertia>
          <pose>0 0 0 0 0 0</pose>
        </inertial>
        <visual name='visual'>
          <pose>-0.040000000000000001 0 0 0 0 0</pose>
          <pose>0 0 0 0 0 0</pose>
          <geometry>
            <mesh>
              <uri>model://prius hybrid/meshes/Hybrid.obj</uri>
              <scale>0.01 0.01 0.01</scale>
              <submesh>
                <name>Wheel_Front_Right</name>
                <center>true</center>
              </submesh>
            </mesh>
          </geometry>
        </visual>
        <collision name='collision'>
          <pose>0 0 0 0 1.5707963267948966 0</pose>
          <geometry>
            <sphere>
              <radius>0.31264999999999998</radius>
            </sphere>
          </geometry>
          <surface>
            <friction>
              <ode>
                <mu>0.90000000000000002</mu>
                <mu2>0.90000000000000002</mu2>
                <slip1>0</slip1>
                <slip2>0</slip2>
              </ode>
            </friction>
            <contact>
              <ode>
                <min_depth>0.001</min_depth>
                <kp>1000000000</kp>
              </ode>
            </contact>
            <bounce/>
          </surface>
        </collision>
        <enable_wind>false</enable_wind>
      </link>
      <link name='rear_left_wheel'>
        <pose>0.78599999999999959 1.4500000000000002 0.29999999999999999 0 0 0</pose>
        <inertial>
          <mass>11</mass>
          <inertia>
            <ixx>0.58631237999999997</ixx>
            <ixy>0</ixy>
            <iyy>0.33552910000000002</iyy>
            <ixz>0</ixz>
            <iyz>0</iyz>
            <izz>0.33552910000000002</izz>
          </inertia>
          <pose>0 0 0 0 0 0</pose>
        </inertial>
        <visual name='visual'>
          <pose>0.040000000000000001 0 0 0 0 0</pose>
          <geometry>
            <mesh>
              <uri>model://prius hybrid/meshes/Hybrid.obj</uri>
              <scale>0.01 0.01 0.01</scale>
              <submesh>
                <name>Wheel_Front_Left_</name>
                <center>true</center>
              </submesh>
            </mesh>
          </geometry>
        </visual>
        <collision name='collision'>
          <pose>0 0 0 0 1.5707963267948966 0</pose>
          <geometry>
            <sphere>
              <radius>0.31264999999999998</radius>
            </sphere>
          </geometry>
          <surface>
            <friction>
              <ode>
                <mu>1.1000000000000001</mu>
                <mu2>1.1000000000000001</mu2>
                <slip1>0</slip1>
                <slip2>0</slip2>
              </ode>
            </friction>
            <contact>
              <ode>
                <min_depth>0.001</min_depth>
                <kp>1000000000</kp>
              </ode>
            </contact>
            <bounce/>
          </surface>
        </collision>
        <enable_wind>false</enable_wind>
      </link>
      <link name='rear_right_wheel'>
        <pose>-0.78599999999999959 1.4500000000000002 0.29999999999999999 0 0 0</pose>
        <inertial>
          <mass>11</mass>
          <inertia>
            <ixx>0.58631237999999997</ixx>
            <ixy>0</ixy>
            <iyy>0.33552910000000002</iyy>
            <ixz>0</ixz>
            <iyz>0</iyz>
            <izz>0.33552910000000002</izz>
          </inertia>
          <pose>0 0 0 0 0 0</pose>
        </inertial>
        <visual name='visual'>
          <pose>-0.040000000000000001 0 0 0 0 0</pose>
          <geometry>
            <mesh>
              <uri>model://prius hybrid/meshes/Hybrid.obj</uri>
              <scale>0.01 0.01 0.01</scale>
              <submesh>
                <name>Wheel_Front_Right</name>
                <center>true</center>
              </submesh>
            </mesh>
          </geometry>
        </visual>
        <collision name='collision'>
          <pose>0 0 0 0 1.5707963267948966 0</pose>
          <geometry>
            <sphere>
              <radius>0.31264999999999998</radius>
            </sphere>
          </geometry>
          <surface>
            <friction>
              <ode>
                <mu>1.1000000000000001</mu>
                <mu2>1.1000000000000001</mu2>
                <slip1>0</slip1>
                <slip2>0</slip2>
              </ode>
            </friction>
            <contact>
              <ode>
                <min_depth>0.001</min_depth>
                <kp>1000000000</kp>
              </ode>
            </contact>
            <bounce/>
          </surface>
        </collision>
        <enable_wind>false</enable_wind>
      </link>
      <joint name='front_left_combined_joint' type='universal'>
        <pose>0 0 0 -0.087266462599716474 0 0</pose>
        <child>front_left_wheel</child>
        <parent>chassis</parent>
        <axis>
          <xyz>0 -4.1633363423443364e-17 1</xyz>
          <limit>
            <lower>-0.87270000000000003</lower>
            <upper>0.87270000000000003</upper>
            <effort>inf</effort>
            <velocity>inf</velocity>
            <stiffness>100000000</stiffness>
            <dissipation>1</dissipation>
          </limit>
          <dynamics>
            <spring_reference>0</spring_reference>
            <spring_stiffness>0</spring_stiffness>
            <damping>0</damping>
            <friction>0</friction>
          </dynamics>
        </axis>
        <axis2>
          <xyz>1 0 0</xyz>
          <limit>
            <lower>-inf</lower>
            <upper>inf</upper>
            <effort>inf</effort>
            <velocity>inf</velocity>
            <stiffness>100000000</stiffness>
            <dissipation>1</dissipation>
          </limit>
          <dynamics>
            <spring_reference>0</spring_reference>
            <spring_stiffness>0</spring_stiffness>
            <damping>0</damping>
            <friction>18.047409225300001</friction>
          </dynamics>
        </axis2>
      </joint>
      <joint name='front_right_combined_joint' type='universal'>
        <pose>0 0 0 -0.087266462599716474 0 0</pose>
        <child>front_right_wheel</child>
        <parent>chassis</parent>
        <axis>
          <xyz>0 -4.1633363423443364e-17 1</xyz>
          <limit>
            <lower>-0.87270000000000003</lower>
            <upper>0.87270000000000003</upper>
            <effort>inf</effort>
            <velocity>inf</velocity>
            <stiffness>100000000</stiffness>
            <dissipation>1</dissipation>
          </limit>
          <dynamics>
            <spring_reference>0</spring_reference>
            <spring_stiffness>0</spring_stiffness>
            <damping>0</damping>
            <friction>0</friction>
          </dynamics>
        </axis>
        <axis2>
          <xyz>1 0 0</xyz>
          <limit>
            <lower>-inf</lower>
            <upper>inf</upper>
            <effort>inf</effort>
            <velocity>inf</velocity>
            <stiffness>100000000</stiffness>
            <dissipation>1</dissipation>
          </limit>
          <dynamics>
            <spring_reference>0</spring_reference>
            <spring_stiffness>0</spring_stiffness>
            <damping>0</damping>
            <friction>18.047409225300001</friction>
          </dynamics>
        </axis2>
      </joint>
      <link name='rear_axle'>
        <pose>0 1.4500000000000002 0.29999999999999999 0 0 0</pose>
        <inertial>
          <mass>30</mass>
          <inertia>
            <ixx>0.084374999999999992</ixx>
            <ixy>0</ixy>
            <iyy>4.64581</iyy>
            <ixz>0</ixz>
            <iyz>0</iyz>
            <izz>4.64581</izz>
          </inertia>
          <pose>0 0 0 0 0 0</pose>
        </inertial>
        <visual name='visual'>
          <pose>0 0 0 0 1.5707963267948966 0</pose>
          <geometry>
            <cylinder>
              <length>1.357</length>
              <radius>0.074999999999999997</radius>
            </cylinder>
          </geometry>
          <material>
            <script>
              <name>Gazebo/Grey</name>
              <uri>file://media/materials/scripts/gazebo.material</uri>
            </script>
          </material>
        </visual>
        <enable_wind>false</enable_wind>
      </link>
      <joint name='rear_axle_joint' type='revolute'>
        <child>rear_axle</child>
        <parent>chassis</parent>
        <axis>
          <xyz>0 1 0</xyz>
          <limit>
            <lower>-0.050890585241730277</lower>
            <upper>0.050890585241730277</upper>
            <effort>inf</effort>
            <velocity>inf</velocity>
            <stiffness>100000000</stiffness>
            <dissipation>1</dissipation>
          </limit>
          <dynamics>
            <spring_reference>0</spring_reference>
            <spring_stiffness>20000</spring_stiffness>
            <damping>2000</damping>
            <friction>0</friction>
          </dynamics>
        </axis>
        <pose>0 0 0 0 0 0</pose>
      </joint>
      <joint name='rear_left_wheel_joint' type='revolute'>
        <child>rear_left_wheel</child>
        <parent>rear_axle</parent>
        <axis>
          <xyz>1 0 0</xyz>
          <limit>
            <lower>-inf</lower>
            <upper>inf</upper>
            <effort>inf</effort>
            <velocity>inf</velocity>
            <stiffness>100000000</stiffness>
            <dissipation>1</dissipation>
          </limit>
          <dynamics>
            <spring_reference>0</spring_reference>
            <spring_stiffness>0</spring_stiffness>
            <damping>0</damping>
            <friction>12.031606150200002</friction>
          </dynamics>
        </axis>
        <pose>0 0 0 0 0 0</pose>
      </joint>
      <joint name='rear_right_wheel_joint' type='revolute'>
        <child>rear_right_wheel</child>
        <parent>rear_axle</parent>
        <axis>
          <xyz>1 0 0</xyz>
          <limit>
            <lower>-inf</lower>
            <upper>inf</upper>
            <effort>inf</effort>
            <velocity>inf</velocity>
            <stiffness>100000000</stiffness>
            <dissipation>1</dissipation>
          </limit>
          <dynamics>
            <spring_reference>0</spring_reference>
            <spring_stiffness>0</spring_stiffness>
            <damping>0</damping>
            <friction>12.031606150200002</friction>
          </dynamics>
        </axis>
        <pose>0 0 0 0 0 0</pose>
      </joint>
      <joint name='steering_joint' type='revolute'>
        <pose>-0.0020000000000000018 2.2204460492503131e-16 5.5511151231257827e-17 0 0 0</pose>
        <parent>chassis</parent>
        <child>steering_wheel</child>
        <axis>
          <xyz>0 -8.5372090472435325e-05 0.99999999635580317</xyz>
          <limit>
            <lower>-7.8499999999999996</lower>
            <upper>7.8499999999999996</upper>
            <effort>inf</effort>
            <velocity>inf</velocity>
            <stiffness>100000000</stiffness>
            <dissipation>1</dissipation>
          </limit>
          <dynamics>
            <spring_reference>0</spring_reference>
            <spring_stiffness>0</spring_stiffness>
            <damping>1</damping>
            <friction>0</friction>
          </dynamics>
        </axis>
        <physics>
          <ode>
            <cfm_damping>true</cfm_damping>
          </ode>
        </physics>
      </joint>
      <static>false</static>
      <self_collide>false</self_collide>
    </model>
    <model name='pedestrian_1'>
      <link name='link'>
        <inertial>
          <pose>0 -0.10000000000000001 0.94999999999999996 0 0 0</pose>
          <mass>80</mass>
          <inertia>
            <ixx>24.879999999999999</ixx>
            <ixy>0</ixy>
            <ixz>0</ixz>
            <iyy>25.73</iyy>
            <iyz>0</iyz>
            <izz>2.48</izz>
          </inertia>
        </inertial>
        <collision name='bottom'>
          <pose>0 -0.10000000000000001 0.01 0 0 0</pose>
          <geometry>
            <box>
              <size>0.5 0.34999999999999998 0.02</size>
            </box>
          </geometry>
          <surface>
            <friction>
              <ode/>
            </friction>
            <bounce/>
            <contact/>
          </surface>
        </collision>
        <collision name='person'>
          <pose>0 0 0.02 0.040000000000000001 0 0</pose>
          <geometry>
            <mesh>
              <uri>model://standing person/meshes/standing.dae</uri>
            </mesh>
          </geometry>
        </collision>
        <visual name='visual'>
          <pose>0 0 0.02 0.040000000000000001 0 0</pose>
          <geometry>
            <mesh>
              <uri>model://standing person/meshes/standing.dae</uri>
            </mesh>
          </geometry>
        </visual>
        <pose>0 0 0 0 0 0</pose>
        <enable_wind>false</enable_wind>
      </link>
      <pose>5 5 0 0 0 0</pose>
      <static>false</static>
      <self_collide>false</self_collide>
    </model>
    <model name='pedestrian_2'>
      <link name='link'>
        <inertial>
          <pose>0 -0.10000000000000001 0.94999999999999996 0 0 0</pose>
          <mass>80</mass>
          <inertia>
            <ixx>24.879999999999999</ixx>
            <ixy>0</ixy>
            <ixz>0</ixz>
            <iyy>25.73</iyy>
            <iyz>0</iyz>
            <izz>2.48</izz>
          </inertia>
        </inertial>
        <collision name='bottom'>
          <pose>0 -0.10000000000000001 0.01 0 0 0</pose>
          <geometry>
            <box>
              <size>0.5 0.34999999999999998 0.02</size>
            </box>
          </geometry>
          <surface>
            <friction>
              <ode/>
            </friction>
            <bounce/>
            <contact/>
          </surface>
        </collision>
        <collision name='person'>
          <pose>0 0 0.02 0.040000000000000001 0 0</pose>
          <geometry>
            <mesh>
              <uri>model://standing person/meshes/standing.dae</uri>
            </mesh>
          </geometry>
        </collision>
        <visual name='visual'>
          <pose>0 0 0.02 0.040000000000000001 0 0</pose>
          <geometry>
            <mesh>
              <uri>model://standing person/meshes/standing.dae</uri>
            </mesh>
          </geometry>
        </visual>
        <pose>0 0 0 0 0 0</pose>
        <enable_wind>false</enable_wind>
      </link>
      <pose>-2 6 0 0 0 0</pose>
      <static>false</static>
      <self_collide>false</self_collide>
    </model>
    <model name='pedestrian_3'>
      <link name='link'>
        <inertial>
          <pose>0 -0.10000000000000001 0.94999999999999996 0 0 0</pose>
          <mass>80</mass>
          <inertia>
            <ixx>24.879999999999999</ixx>
            <ixy>0</ixy>
            <ixz>0</ixz>
            <iyy>25.73</iyy>
            <iyz>0</iyz>
            <izz>2.48</izz>
          </inertia>
        </inertial>
        <collision name='bottom'>
          <pose>0 -0.10000000000000001 0.01 0 0 0</pose>
          <geometry>
            <box>
              <size>0.5 0.34999999999999998 0.02</size>
            </box>
          </geometry>
          <surface>
            <friction>
              <ode/>
            </friction>
            <bounce/>
            <contact/>
          </surface>
        </collision>
        <collision name='person'>
          <pose>0 0 0.02 0.040000000000000001 0 0</pose>
          <geometry>
            <mesh>
              <uri>model://standing person/meshes/standing.dae</uri>
            </mesh>
          </geometry>
        </collision>
        <visual name='visual'>
          <pose>0 0 0.02 0.040000000000000001 0 0</pose>
          <geometry>
            <mesh>
              <uri>model://standing person/meshes/standing.dae</uri>
            </mesh>
          </geometry>
        </visual>
        <pose>0 0 0 0 0 0</pose>
        <enable_wind>false</enable_wind>
      </link>
      <pose>8 3 0 0 0 0</pose>
      <static>false</static>
      <self_collide>false</self_collide>
    </model>
    <model name='drop_zone_qrcode'>
      <static>true</static>
      <pose>5 0 0.01 0 0 0</pose>
      <link name='landing_pad'>
        <collision name='pad_col'>
          <geometry>
            <box>
              <size>2 2 0.02</size>
            </box>
          </geometry>
          <surface>
            <friction>
              <ode/>
            </friction>
            <bounce/>
            <contact/>
          </surface>
        </collision>
        <visual name='pad_vis'>
          <geometry>
            <box>
              <size>2 2 0.02</size>
            </box>
          </geometry>
          <material>
            <ambient>1 1 1 1</ambient>
            <diffuse>1 1 1 1</diffuse>
            <pbr>
              <metal>
                <albedo_map>file://world/delivery_point.png</albedo_map>
              </metal>
            </pbr>
          </material>
        </visual>
        <pose>0 0 0 0 0 0</pose>
        <inertial>
          <pose>0 0 0 0 0 0</pose>
          <mass>1</mass>
          <inertia>
            <ixx>1</ixx>
            <ixy>0</ixy>
            <ixz>0</ixz>
            <iyy>1</iyy>
            <iyz>0</iyz>
            <izz>1</izz>
          </inertia>
        </inertial>
        <enable_wind>false</enable_wind>
      </link>
      <self_collide>false</self_collide>
    </model>
    <model name='pedestrian_3_1'>
      <link name='link'>
        <inertial>
          <pose>0 -0.10000000000000001 0.94999999999999996 0 0 0</pose>
          <mass>80</mass>
          <inertia>
            <ixx>24.879999999999999</ixx>
            <ixy>0</ixy>
            <ixz>0</ixz>
            <iyy>25.73</iyy>
            <iyz>0</iyz>
            <izz>2.48</izz>
          </inertia>
        </inertial>
        <collision name='bottom'>
          <pose>0 -0.10000000000000001 0.01 0 0 0</pose>
          <geometry>
            <box>
              <size>0.5 0.34999999999999998 0.02</size>
            </box>
          </geometry>
          <surface>
            <friction>
              <ode/>
            </friction>
            <bounce/>
            <contact/>
          </surface>
        </collision>
        <collision name='person'>
          <pose>0 0 0.02 0.040000000000000001 0 0</pose>
          <geometry>
            <mesh>
              <uri>model://standing person/meshes/standing.dae</uri>
            </mesh>
          </geometry>
        </collision>
        <visual name='visual'>
          <pose>0 0 0.02 0.040000000000000001 0 0</pose>
          <geometry>
            <mesh>
              <uri>model://standing person/meshes/standing.dae</uri>
            </mesh>
          </geometry>
        </visual>
        <pose>0 0 0 0 0 0</pose>
        <enable_wind>false</enable_wind>
      </link>
      <pose>3.1629930055525337 2.3767581774950783 0 0 0 0</pose>
      <static>false</static>
      <self_collide>false</self_collide>
    </model>
    <model name='tree_4_2'>
      <static>true</static>
      <link name='link'>
        <collision name='collision'>
          <geometry>
            <mesh>
              <uri>model://pine tree/meshes/pine_tree.dae</uri>
            </mesh>
          </geometry>
        </collision>
        <visual name='branch'>
          <geometry>
            <mesh>
              <uri>model://pine tree/meshes/pine_tree.dae</uri>
              <submesh>
                <name>Branch</name>
              </submesh>
            </mesh>
          </geometry>
          <material>
            <double_sided>true</double_sided>
            <diffuse>1 1 1 1</diffuse>
            <script>
              <uri>model://pine tree/materials/scripts/</uri>
              <uri>model://pine tree/materials/textures/</uri>
              <name>PineTree/Branch</name>
            </script>
            <pbr>
              <metal>
                <albedo_map>model://pine tree/materials/textures/branch_2_diffuse.png</albedo_map>
              </metal>
            </pbr>
          </material>
        </visual>
        <visual name='bark'>
          <geometry>
            <mesh>
              <uri>model://pine tree/meshes/pine_tree.dae</uri>
              <submesh>
                <name>Bark</name>
              </submesh>
            </mesh>
          </geometry>
          <material>
            <diffuse>1 1 1 1</diffuse>
            <script>
              <uri>model://pine tree/materials/scripts/</uri>
              <uri>model://pine tree/materials/textures/</uri>
              <name>PineTree/Bark</name>
            </script>
            <pbr>
              <metal>
                <albedo_map>model://pine tree/materials/textures/bark_diffuse.png</albedo_map>
              </metal>
            </pbr>
          </material>
        </visual>
        <pose>0 0 0 0 0 0</pose>
        <inertial>
          <pose>0 0 0 0 0 0</pose>
          <mass>1</mass>
          <inertia>
            <ixx>1</ixx>
            <ixy>0</ixy>
            <ixz>0</ixz>
            <iyy>1</iyy>
            <iyz>0</iyz>
            <izz>1</izz>
          </inertia>
        </inertial>
        <enable_wind>false</enable_wind>
      </link>
      <pose>7.723000263292497 5.5905149973917769 0 0 0 0</pose>
      <self_collide>false</self_collide>
    </model>
    <model name='vehicle_1_1'>
      <pose>0.71469032042345226 -1.4547586190747719 0 0 0 0</pose>
      <link name='chassis'>
        <inertial>
          <mass>1326</mass>
          <pose>0 -0.26600000000000001 0.47999999999999998 0 0 0</pose>
          <inertia>
            <ixx>2581.1335474000002</ixx>
            <ixy>0</ixy>
            <iyy>591.30846111999995</iyy>
            <ixz>0</ixz>
            <iyz>0</iyz>
            <izz>2681.9500862800001</izz>
          </inertia>
        </inertial>
        <visual name='chassis_visual'>
          <geometry>
            <mesh>
              <uri>model://prius hybrid/meshes/Hybrid.obj</uri>
              <scale>0.01 0.01 0.01</scale>
              <submesh>
                <name>Hybrid</name>
                <center>false</center>
              </submesh>
            </mesh>
          </geometry>
        </visual>
        <visual name='interior_visual'>
          <geometry>
            <mesh>
              <uri>model://prius hybrid/meshes/Hybrid.obj</uri>
              <scale>0.01 0.01 0.01</scale>
              <submesh>
                <name>Hybrid_Interior</name>
                <center>false</center>
              </submesh>
            </mesh>
          </geometry>
        </visual>
        <visual name='windows_visual'>
          <geometry>
            <mesh>
              <uri>model://prius hybrid/meshes/Hybrid.obj</uri>
              <scale>0.01 0.01 0.01</scale>
              <submesh>
                <name>Hybrid_Windows</name>
                <center>false</center>
              </submesh>
            </mesh>
          </geometry>
        </visual>
        <collision name='chassis'>
          <pose>0 0.050000000000000003 0.625 0 0 0</pose>
          <geometry>
            <box>
              <size>1.7525999999999999 2.1000000000000001 0.94999999999999996</size>
            </box>
          </geometry>
          <surface>
            <friction>
              <ode/>
            </friction>
            <bounce/>
            <contact/>
          </surface>
        </collision>
        <collision name='front_bumper'>
          <pose>0 -2 0.45848800000000001 0 0 0</pose>
          <geometry>
            <box>
              <size>1.3372820000000001 0.47999999999999998 0.56669099999999994</size>
            </box>
          </geometry>
          <surface>
            <friction>
              <ode/>
            </friction>
            <bounce/>
            <contact/>
          </surface>
        </collision>
        <collision name='hood'>
          <pose>0 -1.9008419999999999 0.67630500000000005 0.34124700000000019 0 0</pose>
          <geometry>
            <box>
              <size>1.5979680000000001 0.49310700000000002 0.26546799999999998</size>
            </box>
          </geometry>
          <surface>
            <friction>
              <ode/>
            </friction>
            <bounce/>
            <contact/>
          </surface>
        </collision>
        <collision name='windshield'>
          <pose>0 -0.87510500000000002 1.032268 0.335476 0 0</pose>
          <geometry>
            <box>
              <size>1.1683809999999999 1.654253 0.27234700000000001</size>
            </box>
          </geometry>
          <surface>
            <friction>
              <ode/>
            </friction>
            <bounce/>
            <contact/>
          </surface>
        </collision>
        <collision name='top_front'>
          <pose>0 0.16123599999999999 1.386042 0.13503000000000009 0 0</pose>
          <geometry>
            <box>
              <size>1.2791539999999999 0.62598799999999999 0.17186799999999999</size>
            </box>
          </geometry>
          <surface>
            <friction>
              <ode/>
            </friction>
            <bounce/>
            <contact/>
          </surface>
        </collision>
        <collision name='top_rear'>
          <pose>0 0.81769599999999998 1.360069 -0.068997000000000003 0 0</pose>
          <geometry>
            <box>
              <size>1.2851300000000001 0.77118900000000001 0.22655700000000001</size>
            </box>
          </geometry>
          <surface>
            <friction>
              <ode/>
            </friction>
            <bounce/>
            <contact/>
          </surface>
        </collision>
        <collision name='rear_window'>
          <pose>0 1.640531 1.1751259999999999 -0.26201699999999983 0 0</pose>
          <geometry>
            <box>
              <size>1.2678450000000001 1.116344 0.244286</size>
            </box>
          </geometry>
          <surface>
            <friction>
              <ode/>
            </friction>
            <bounce/>
            <contact/>
          </surface>
        </collision>
        <collision name='trunk'>
          <pose>0 1.637059 0.88817999999999997 0 0 0</pose>
          <geometry>
            <box>
              <size>1.7880640000000001 1.1389879999999999 0.48274600000000001</size>
            </box>
          </geometry>
          <surface>
            <friction>
              <ode/>
            </friction>
            <bounce/>
            <contact/>
          </surface>
        </collision>
        <collision name='back_bumper'>
          <pose>0 2.0544539999999998 0.57786999999999999 0 0 0</pose>
          <geometry>
            <box>
              <size>1.78165 0.51209300000000002 0.58142700000000003</size>
            </box>
          </geometry>
          <surface>
            <friction>
              <ode/>
            </friction>
            <bounce/>
            <contact/>
          </surface>
        </collision>
        <pose>0 0 0 0 0 0</pose>
        <enable_wind>false</enable_wind>
      </link>
      <link name='steering_wheel'>
        <pose>0.35773399999999977 -0.62786800000000031 0.98824299999999976 -1.3021010000000011 0 0</pose>
        <inertial>
          <mass>1</mass>
          <inertia>
            <ixx>0.14583299999999999</ixx>
            <ixy>0</ixy>
            <ixz>0</ixz>
            <iyy>0.14583299999999999</iyy>
            <iyz>0</iyz>
            <izz>0.125</izz>
          </inertia>
          <pose>0 0 0 0 0 0</pose>
        </inertial>
        <collision name='collision'>
          <geometry>
            <cylinder>
              <radius>0.178172</radius>
              <length>0.041845</length>
            </cylinder>
          </geometry>
          <surface>
            <contact>
              <ode>
                <min_depth>0.0030000000000000001</min_depth>
              </ode>
            </contact>
            <friction>
              <ode/>
            </friction>
            <bounce/>
          </surface>
        </collision>
        <visual name='visual'>
          <pose>0 0 0 1.302101 0 0</pose>
          <geometry>
            <mesh>
              <uri>model://prius hybrid/meshes/Hybrid.obj</uri>
              <scale>0.01 0.01 0.01</scale>
              <submesh>
                <name>Steering_Wheel</name>
                <center>true</center>
              </submesh>
            </mesh>
          </geometry>
        </visual>
        <enable_wind>false</enable_wind>
      </link>
      <link name='front_left_wheel'>
        <pose>0.75999999999999979 -1.4100000000000001 0.29999999999999999 0 0 0</pose>
        <inertial>
          <mass>11</mass>
          <inertia>
            <ixx>0.58631237999999997</ixx>
            <ixy>0</ixy>
            <iyy>0.33552910000000002</iyy>
            <ixz>0</ixz>
            <iyz>0</iyz>
            <izz>0.33552910000000002</izz>
          </inertia>
          <pose>0 0 0 0 0 0</pose>
        </inertial>
        <visual name='visual'>
          <pose>0.040000000000000001 0 0 0 0 0</pose>
          <geometry>
            <mesh>
              <uri>model://prius hybrid/meshes/Hybrid.obj</uri>
              <scale>0.01 0.01 0.01</scale>
              <submesh>
                <name>Wheel_Front_Left_</name>
                <center>true</center>
              </submesh>
            </mesh>
          </geometry>
        </visual>
        <collision name='collision'>
          <pose>0 0 0 0 1.5707963267948966 0</pose>
          <geometry>
            <sphere>
              <radius>0.31264999999999998</radius>
            </sphere>
          </geometry>
          <surface>
            <friction>
              <ode>
                <mu>0.90000000000000002</mu>
                <mu2>0.90000000000000002</mu2>
                <slip1>0</slip1>
                <slip2>0</slip2>
              </ode>
            </friction>
            <contact>
              <ode>
                <min_depth>0.001</min_depth>
                <kp>1000000000</kp>
              </ode>
            </contact>
            <bounce/>
          </surface>
        </collision>
        <enable_wind>false</enable_wind>
      </link>
      <link name='front_right_wheel'>
        <pose>-0.75999999999999979 -1.4100000000000001 0.29999999999999999 0 0 0</pose>
        <inertial>
          <mass>11</mass>
          <inertia>
            <ixx>0.58631237999999997</ixx>
            <ixy>0</ixy>
            <iyy>0.33552910000000002</iyy>
            <ixz>0</ixz>
            <iyz>0</iyz>
            <izz>0.33552910000000002</izz>
          </inertia>
          <pose>0 0 0 0 0 0</pose>
        </inertial>
        <visual name='visual'>
          <pose>-0.040000000000000001 0 0 0 0 0</pose>
          <pose>0 0 0 0 0 0</pose>
          <geometry>
            <mesh>
              <uri>model://prius hybrid/meshes/Hybrid.obj</uri>
              <scale>0.01 0.01 0.01</scale>
              <submesh>
                <name>Wheel_Front_Right</name>
                <center>true</center>
              </submesh>
            </mesh>
          </geometry>
        </visual>
        <collision name='collision'>
          <pose>0 0 0 0 1.5707963267948966 0</pose>
          <geometry>
            <sphere>
              <radius>0.31264999999999998</radius>
            </sphere>
          </geometry>
          <surface>
            <friction>
              <ode>
                <mu>0.90000000000000002</mu>
                <mu2>0.90000000000000002</mu2>
                <slip1>0</slip1>
                <slip2>0</slip2>
              </ode>
            </friction>
            <contact>
              <ode>
                <min_depth>0.001</min_depth>
                <kp>1000000000</kp>
              </ode>
            </contact>
            <bounce/>
          </surface>
        </collision>
        <enable_wind>false</enable_wind>
      </link>
      <link name='rear_left_wheel'>
        <pose>0.78599999999999959 1.4500000000000002 0.29999999999999999 0 0 0</pose>
        <inertial>
          <mass>11</mass>
          <inertia>
            <ixx>0.58631237999999997</ixx>
            <ixy>0</ixy>
            <iyy>0.33552910000000002</iyy>
            <ixz>0</ixz>
            <iyz>0</iyz>
            <izz>0.33552910000000002</izz>
          </inertia>
          <pose>0 0 0 0 0 0</pose>
        </inertial>
        <visual name='visual'>
          <pose>0.040000000000000001 0 0 0 0 0</pose>
          <geometry>
            <mesh>
              <uri>model://prius hybrid/meshes/Hybrid.obj</uri>
              <scale>0.01 0.01 0.01</scale>
              <submesh>
                <name>Wheel_Front_Left_</name>
                <center>true</center>
              </submesh>
            </mesh>
          </geometry>
        </visual>
        <collision name='collision'>
          <pose>0 0 0 0 1.5707963267948966 0</pose>
          <geometry>
            <sphere>
              <radius>0.31264999999999998</radius>
            </sphere>
          </geometry>
          <surface>
            <friction>
              <ode>
                <mu>1.1000000000000001</mu>
                <mu2>1.1000000000000001</mu2>
                <slip1>0</slip1>
                <slip2>0</slip2>
              </ode>
            </friction>
            <contact>
              <ode>
                <min_depth>0.001</min_depth>
                <kp>1000000000</kp>
              </ode>
            </contact>
            <bounce/>
          </surface>
        </collision>
        <enable_wind>false</enable_wind>
      </link>
      <link name='rear_right_wheel'>
        <pose>-0.78599999999999959 1.4500000000000002 0.29999999999999999 0 0 0</pose>
        <inertial>
          <mass>11</mass>
          <inertia>
            <ixx>0.58631237999999997</ixx>
            <ixy>0</ixy>
            <iyy>0.33552910000000002</iyy>
            <ixz>0</ixz>
            <iyz>0</iyz>
            <izz>0.33552910000000002</izz>
          </inertia>
          <pose>0 0 0 0 0 0</pose>
        </inertial>
        <visual name='visual'>
          <pose>-0.040000000000000001 0 0 0 0 0</pose>
          <geometry>
            <mesh>
              <uri>model://prius hybrid/meshes/Hybrid.obj</uri>
              <scale>0.01 0.01 0.01</scale>
              <submesh>
                <name>Wheel_Front_Right</name>
                <center>true</center>
              </submesh>
            </mesh>
          </geometry>
        </visual>
        <collision name='collision'>
          <pose>0 0 0 0 1.5707963267948966 0</pose>
          <geometry>
            <sphere>
              <radius>0.31264999999999998</radius>
            </sphere>
          </geometry>
          <surface>
            <friction>
              <ode>
                <mu>1.1000000000000001</mu>
                <mu2>1.1000000000000001</mu2>
                <slip1>0</slip1>
                <slip2>0</slip2>
              </ode>
            </friction>
            <contact>
              <ode>
                <min_depth>0.001</min_depth>
                <kp>1000000000</kp>
              </ode>
            </contact>
            <bounce/>
          </surface>
        </collision>
        <enable_wind>false</enable_wind>
      </link>
      <joint name='front_left_combined_joint' type='universal'>
        <pose>0 0 0 -0.087266462599716474 0 0</pose>
        <child>front_left_wheel</child>
        <parent>chassis</parent>
        <axis>
          <xyz>0 -2.775557561562891e-17 1</xyz>
          <limit>
            <lower>-0.87270000000000003</lower>
            <upper>0.87270000000000003</upper>
            <effort>inf</effort>
            <velocity>inf</velocity>
            <stiffness>100000000</stiffness>
            <dissipation>1</dissipation>
          </limit>
          <dynamics>
            <spring_reference>0</spring_reference>
            <spring_stiffness>0</spring_stiffness>
            <damping>0</damping>
            <friction>0</friction>
          </dynamics>
        </axis>
        <axis2>
          <xyz>1 0 0</xyz>
          <limit>
            <lower>-inf</lower>
            <upper>inf</upper>
            <effort>inf</effort>
            <velocity>inf</velocity>
            <stiffness>100000000</stiffness>
            <dissipation>1</dissipation>
          </limit>
          <dynamics>
            <spring_reference>0</spring_reference>
            <spring_stiffness>0</spring_stiffness>
            <damping>0</damping>
            <friction>18.047409225300001</friction>
          </dynamics>
        </axis2>
      </joint>
      <joint name='front_right_combined_joint' type='universal'>
        <pose>0 0 0 -0.087266462599716474 0 0</pose>
        <child>front_right_wheel</child>
        <parent>chassis</parent>
        <axis>
          <xyz>0 -2.775557561562891e-17 1</xyz>
          <limit>
            <lower>-0.87270000000000003</lower>
            <upper>0.87270000000000003</upper>
            <effort>inf</effort>
            <velocity>inf</velocity>
            <stiffness>100000000</stiffness>
            <dissipation>1</dissipation>
          </limit>
          <dynamics>
            <spring_reference>0</spring_reference>
            <spring_stiffness>0</spring_stiffness>
            <damping>0</damping>
            <friction>0</friction>
          </dynamics>
        </axis>
        <axis2>
          <xyz>1 0 0</xyz>
          <limit>
            <lower>-inf</lower>
            <upper>inf</upper>
            <effort>inf</effort>
            <velocity>inf</velocity>
            <stiffness>100000000</stiffness>
            <dissipation>1</dissipation>
          </limit>
          <dynamics>
            <spring_reference>0</spring_reference>
            <spring_stiffness>0</spring_stiffness>
            <damping>0</damping>
            <friction>18.047409225300001</friction>
          </dynamics>
        </axis2>
      </joint>
      <link name='rear_axle'>
        <pose>0 1.4500000000000002 0.29999999999999999 0 0 0</pose>
        <inertial>
          <mass>30</mass>
          <inertia>
            <ixx>0.084374999999999992</ixx>
            <ixy>0</ixy>
            <iyy>4.64581</iyy>
            <ixz>0</ixz>
            <iyz>0</iyz>
            <izz>4.64581</izz>
          </inertia>
          <pose>0 0 0 0 0 0</pose>
        </inertial>
        <visual name='visual'>
          <pose>0 0 0 0 1.5707963267948966 0</pose>
          <geometry>
            <cylinder>
              <length>1.357</length>
              <radius>0.074999999999999997</radius>
            </cylinder>
          </geometry>
          <material>
            <script>
              <name>Gazebo/Grey</name>
              <uri>file://media/materials/scripts/gazebo.material</uri>
            </script>
          </material>
        </visual>
        <enable_wind>false</enable_wind>
      </link>
      <joint name='rear_axle_joint' type='revolute'>
        <child>rear_axle</child>
        <parent>chassis</parent>
        <axis>
          <xyz>0 1 0</xyz>
          <limit>
            <lower>-0.050890585241730277</lower>
            <upper>0.050890585241730277</upper>
            <effort>inf</effort>
            <velocity>inf</velocity>
            <stiffness>100000000</stiffness>
            <dissipation>1</dissipation>
          </limit>
          <dynamics>
            <spring_reference>0</spring_reference>
            <spring_stiffness>20000</spring_stiffness>
            <damping>2000</damping>
            <friction>0</friction>
          </dynamics>
        </axis>
        <pose>0 0 0 0 0 0</pose>
      </joint>
      <joint name='rear_left_wheel_joint' type='revolute'>
        <child>rear_left_wheel</child>
        <parent>rear_axle</parent>
        <axis>
          <xyz>1 0 0</xyz>
          <limit>
            <lower>-inf</lower>
            <upper>inf</upper>
            <effort>inf</effort>
            <velocity>inf</velocity>
            <stiffness>100000000</stiffness>
            <dissipation>1</dissipation>
          </limit>
          <dynamics>
            <spring_reference>0</spring_reference>
            <spring_stiffness>0</spring_stiffness>
            <damping>0</damping>
            <friction>12.031606150200002</friction>
          </dynamics>
        </axis>
        <pose>0 0 0 0 0 0</pose>
      </joint>
      <joint name='rear_right_wheel_joint' type='revolute'>
        <child>rear_right_wheel</child>
        <parent>rear_axle</parent>
        <axis>
          <xyz>1 0 0</xyz>
          <limit>
            <lower>-inf</lower>
            <upper>inf</upper>
            <effort>inf</effort>
            <velocity>inf</velocity>
            <stiffness>100000000</stiffness>
            <dissipation>1</dissipation>
          </limit>
          <dynamics>
            <spring_reference>0</spring_reference>
            <spring_stiffness>0</spring_stiffness>
            <damping>0</damping>
            <friction>12.031606150200002</friction>
          </dynamics>
        </axis>
        <pose>0 0 0 0 0 0</pose>
      </joint>
      <joint name='steering_joint' type='revolute'>
        <pose>-0.0020000000000000573 0 -5.5511151231257827e-17 0 0 0</pose>
        <parent>chassis</parent>
        <child>steering_wheel</child>
        <axis>
          <xyz>0 -8.5372090472435325e-05 0.99999999635580317</xyz>
          <limit>
            <lower>-7.8499999999999996</lower>
            <upper>7.8499999999999996</upper>
            <effort>inf</effort>
            <velocity>inf</velocity>
            <stiffness>100000000</stiffness>
            <dissipation>1</dissipation>
          </limit>
          <dynamics>
            <spring_reference>0</spring_reference>
            <spring_stiffness>0</spring_stiffness>
            <damping>1</damping>
            <friction>0</friction>
          </dynamics>
        </axis>
        <physics>
          <ode>
            <cfm_damping>true</cfm_damping>
          </ode>
        </physics>
      </joint>
      <static>false</static>
      <self_collide>false</self_collide>
    </model>
    <model name='tree_1_1'>
      <static>true</static>
      <link name='link'>
        <collision name='collision'>
          <geometry>
            <mesh>
              <uri>model://oak tree/meshes/oak_tree.dae</uri>
            </mesh>
          </geometry>
        </collision>
        <visual name='branch'>
          <geometry>
            <mesh>
              <uri>model://oak tree/meshes/oak_tree.dae</uri>
              <submesh>
                <name>Branch</name>
              </submesh>
            </mesh>
          </geometry>
          <material>
            <double_sided>true</double_sided>
            <diffuse>1 1 1 1</diffuse>
            <script>
              <uri>model://oak tree/materials/scripts/</uri>
              <uri>model://oak tree/materials/textures/</uri>
              <name>OakTree/Branch</name>
            </script>
            <pbr>
              <metal>
                <albedo_map>model://oak tree/materials/textures/branch_diffuse.png</albedo_map>
              </metal>
            </pbr>
          </material>
        </visual>
        <visual name='bark'>
          <geometry>
            <mesh>
              <uri>model://oak tree/meshes/oak_tree.dae</uri>
              <submesh>
                <name>Bark</name>
              </submesh>
            </mesh>
          </geometry>
          <material>
            <diffuse>1 1 1 1</diffuse>
            <script>
              <uri>model://oak tree/materials/scripts/</uri>
              <uri>model://oak tree/materials/textures/</uri>
              <name>OakTree/Bark</name>
            </script>
            <pbr>
              <metal>
                <albedo_map>model://oak tree/materials/textures/bark_diffuse.png</albedo_map>
              </metal>
            </pbr>
          </material>
        </visual>
        <pose>0 0 0 0 0 0</pose>
        <inertial>
          <pose>0 0 0 0 0 0</pose>
          <mass>1</mass>
          <inertia>
            <ixx>1</ixx>
            <ixy>0</ixy>
            <ixz>0</ixz>
            <iyy>1</iyy>
            <iyz>0</iyz>
            <izz>1</izz>
          </inertia>
        </inertial>
        <enable_wind>false</enable_wind>
      </link>
      <pose>4.2193253784353129 13.57758714075382 0 0 0 0</pose>
      <self_collide>false</self_collide>
    </model>
    <model name='pedestrian_2_1'>
      <link name='link'>
        <inertial>
          <pose>0 -0.10000000000000001 0.94999999999999996 0 0 0</pose>
          <mass>80</mass>
          <inertia>
            <ixx>24.879999999999999</ixx>
            <ixy>0</ixy>
            <ixz>0</ixz>
            <iyy>25.73</iyy>
            <iyz>0</iyz>
            <izz>2.48</izz>
          </inertia>
        </inertial>
        <collision name='bottom'>
          <pose>0 -0.10000000000000001 0.01 0 0 0</pose>
          <geometry>
            <box>
              <size>0.5 0.34999999999999998 0.02</size>
            </box>
          </geometry>
          <surface>
            <friction>
              <ode/>
            </friction>
            <bounce/>
            <contact/>
          </surface>
        </collision>
        <collision name='person'>
          <pose>0 0 0.02 0.040000000000000001 0 0</pose>
          <geometry>
            <mesh>
              <uri>model://standing person/meshes/standing.dae</uri>
            </mesh>
          </geometry>
        </collision>
        <visual name='visual'>
          <pose>0 0 0.02 0.040000000000000001 0 0</pose>
          <geometry>
            <mesh>
              <uri>model://standing person/meshes/standing.dae</uri>
            </mesh>
          </geometry>
        </visual>
        <pose>0 0 0 0 0 0</pose>
        <enable_wind>false</enable_wind>
      </link>
      <pose>-3.7862825812147172 4.0236279775579638 0 0 0 0</pose>
      <static>false</static>
      <self_collide>false</self_collide>
    </model>
    <model name='pedestrian_2_2'>
      <link name='link'>
        <inertial>
          <pose>0 -0.10000000000000001 0.94999999999999996 0 0 0</pose>
          <mass>80</mass>
          <inertia>
            <ixx>24.879999999999999</ixx>
            <ixy>0</ixy>
            <ixz>0</ixz>
            <iyy>25.73</iyy>
            <iyz>0</iyz>
            <izz>2.48</izz>
          </inertia>
        </inertial>
        <collision name='bottom'>
          <pose>0 -0.10000000000000001 0.01 0 0 0</pose>
          <geometry>
            <box>
              <size>0.5 0.34999999999999998 0.02</size>
            </box>
          </geometry>
          <surface>
            <friction>
              <ode/>
            </friction>
            <bounce/>
            <contact/>
          </surface>
        </collision>
        <collision name='person'>
          <pose>0 0 0.02 0.040000000000000001 0 0</pose>
          <geometry>
            <mesh>
              <uri>model://standing person/meshes/standing.dae</uri>
            </mesh>
          </geometry>
        </collision>
        <visual name='visual'>
          <pose>0 0 0.02 0.040000000000000001 0 0</pose>
          <geometry>
            <mesh>
              <uri>model://standing person/meshes/standing.dae</uri>
            </mesh>
          </geometry>
        </visual>
        <pose>0 0 0 0 0 0</pose>
        <enable_wind>false</enable_wind>
      </link>
      <pose>-3.5346454225669621 0.32504309293736133 0 0 0 0</pose>
      <static>false</static>
      <self_collide>false</self_collide>
    </model>
    <model name='pedestrian_2_3'>
      <link name='link'>
        <inertial>
          <pose>0 -0.10000000000000001 0.94999999999999996 0 0 0</pose>
          <mass>80</mass>
          <inertia>
            <ixx>24.879999999999999</ixx>
            <ixy>0</ixy>
            <ixz>0</ixz>
            <iyy>25.73</iyy>
            <iyz>0</iyz>
            <izz>2.48</izz>
          </inertia>
        </inertial>
        <collision name='bottom'>
          <pose>0 -0.10000000000000001 0.01 0 0 0</pose>
          <geometry>
            <box>
              <size>0.5 0.34999999999999998 0.02</size>
            </box>
          </geometry>
          <surface>
            <friction>
              <ode/>
            </friction>
            <bounce/>
            <contact/>
          </surface>
        </collision>
        <collision name='person'>
          <pose>0 0 0.02 0.040000000000000001 0 0</pose>
          <geometry>
            <mesh>
              <uri>model://standing person/meshes/standing.dae</uri>
            </mesh>
          </geometry>
        </collision>
        <visual name='visual'>
          <pose>0 0 0.02 0.040000000000000001 0 0</pose>
          <geometry>
            <mesh>
              <uri>model://standing person/meshes/standing.dae</uri>
            </mesh>
          </geometry>
        </visual>
        <pose>0 0 0 0 0 0</pose>
        <enable_wind>false</enable_wind>
      </link>
      <pose>-6.7629009718072428 0.38549686475609324 0 0 0 0</pose>
      <static>false</static>
      <self_collide>false</self_collide>
    </model>
    <model name='pedestrian_2_4'>
      <link name='link'>
        <inertial>
          <pose>0 -0.10000000000000001 0.94999999999999996 0 0 0</pose>
          <mass>80</mass>
          <inertia>
            <ixx>24.879999999999999</ixx>
            <ixy>0</ixy>
            <ixz>0</ixz>
            <iyy>25.73</iyy>
            <iyz>0</iyz>
            <izz>2.48</izz>
          </inertia>
        </inertial>
        <collision name='bottom'>
          <pose>0 -0.10000000000000001 0.01 0 0 0</pose>
          <geometry>
            <box>
              <size>0.5 0.34999999999999998 0.02</size>
            </box>
          </geometry>
          <surface>
            <friction>
              <ode/>
            </friction>
            <bounce/>
            <contact/>
          </surface>
        </collision>
        <collision name='person'>
          <pose>0 0 0.02 0.040000000000000001 0 0</pose>
          <geometry>
            <mesh>
              <uri>model://standing person/meshes/standing.dae</uri>
            </mesh>
          </geometry>
        </collision>
        <visual name='visual'>
          <pose>0 0 0.02 0.040000000000000001 0 0</pose>
          <geometry>
            <mesh>
              <uri>model://standing person/meshes/standing.dae</uri>
            </mesh>
          </geometry>
        </visual>
        <pose>0 0 0 0 0 0</pose>
        <enable_wind>false</enable_wind>
      </link>
      <pose>-4.4379252331134271 -3.7358243210193027 0 0 0 0</pose>
      <static>false</static>
      <self_collide>false</self_collide>
    </model>
    <model name='vehicle_1_1_1'>
      <pose>1.2191604529545401 6.2296902299384733 0 0 0 0</pose>
      <link name='chassis'>
        <inertial>
          <mass>1326</mass>
          <pose>0 -0.26600000000000001 0.47999999999999998 0 0 0</pose>
          <inertia>
            <ixx>2581.1335474000002</ixx>
            <ixy>0</ixy>
            <iyy>591.30846111999995</iyy>
            <ixz>0</ixz>
            <iyz>0</iyz>
            <izz>2681.9500862800001</izz>
          </inertia>
        </inertial>
        <visual name='chassis_visual'>
          <geometry>
            <mesh>
              <uri>model://prius hybrid/meshes/Hybrid.obj</uri>
              <scale>0.01 0.01 0.01</scale>
              <submesh>
                <name>Hybrid</name>
                <center>false</center>
              </submesh>
            </mesh>
          </geometry>
        </visual>
        <visual name='interior_visual'>
          <geometry>
            <mesh>
              <uri>model://prius hybrid/meshes/Hybrid.obj</uri>
              <scale>0.01 0.01 0.01</scale>
              <submesh>
                <name>Hybrid_Interior</name>
                <center>false</center>
              </submesh>
            </mesh>
          </geometry>
        </visual>
        <visual name='windows_visual'>
          <geometry>
            <mesh>
              <uri>model://prius hybrid/meshes/Hybrid.obj</uri>
              <scale>0.01 0.01 0.01</scale>
              <submesh>
                <name>Hybrid_Windows</name>
                <center>false</center>
              </submesh>
            </mesh>
          </geometry>
        </visual>
        <collision name='chassis'>
          <pose>0 0.050000000000000003 0.625 0 0 0</pose>
          <geometry>
            <box>
              <size>1.7525999999999999 2.1000000000000001 0.94999999999999996</size>
            </box>
          </geometry>
          <surface>
            <friction>
              <ode/>
            </friction>
            <bounce/>
            <contact/>
          </surface>
        </collision>
        <collision name='front_bumper'>
          <pose>0 -2 0.45848800000000001 0 0 0</pose>
          <geometry>
            <box>
              <size>1.3372820000000001 0.47999999999999998 0.56669099999999994</size>
            </box>
          </geometry>
          <surface>
            <friction>
              <ode/>
            </friction>
            <bounce/>
            <contact/>
          </surface>
        </collision>
        <collision name='hood'>
          <pose>0 -1.9008419999999999 0.67630500000000005 0.34124700000000019 0 0</pose>
          <geometry>
            <box>
              <size>1.5979680000000001 0.49310700000000002 0.26546799999999998</size>
            </box>
          </geometry>
          <surface>
            <friction>
              <ode/>
            </friction>
            <bounce/>
            <contact/>
          </surface>
        </collision>
        <collision name='windshield'>
          <pose>0 -0.87510500000000002 1.032268 0.335476 0 0</pose>
          <geometry>
            <box>
              <size>1.1683809999999999 1.654253 0.27234700000000001</size>
            </box>
          </geometry>
          <surface>
            <friction>
              <ode/>
            </friction>
            <bounce/>
            <contact/>
          </surface>
        </collision>
        <collision name='top_front'>
          <pose>0 0.16123599999999999 1.386042 0.13503000000000009 0 0</pose>
          <geometry>
            <box>
              <size>1.2791539999999999 0.62598799999999999 0.17186799999999999</size>
            </box>
          </geometry>
          <surface>
            <friction>
              <ode/>
            </friction>
            <bounce/>
            <contact/>
          </surface>
        </collision>
        <collision name='top_rear'>
          <pose>0 0.81769599999999998 1.360069 -0.068997000000000003 0 0</pose>
          <geometry>
            <box>
              <size>1.2851300000000001 0.77118900000000001 0.22655700000000001</size>
            </box>
          </geometry>
          <surface>
            <friction>
              <ode/>
            </friction>
            <bounce/>
            <contact/>
          </surface>
        </collision>
        <collision name='rear_window'>
          <pose>0 1.640531 1.1751259999999999 -0.26201699999999983 0 0</pose>
          <geometry>
            <box>
              <size>1.2678450000000001 1.116344 0.244286</size>
            </box>
          </geometry>
          <surface>
            <friction>
              <ode/>
            </friction>
            <bounce/>
            <contact/>
          </surface>
        </collision>
        <collision name='trunk'>
          <pose>0 1.637059 0.88817999999999997 0 0 0</pose>
          <geometry>
            <box>
              <size>1.7880640000000001 1.1389879999999999 0.48274600000000001</size>
            </box>
          </geometry>
          <surface>
            <friction>
              <ode/>
            </friction>
            <bounce/>
            <contact/>
          </surface>
        </collision>
        <collision name='back_bumper'>
          <pose>0 2.0544539999999998 0.57786999999999999 0 0 0</pose>
          <geometry>
            <box>
              <size>1.78165 0.51209300000000002 0.58142700000000003</size>
            </box>
          </geometry>
          <surface>
            <friction>
              <ode/>
            </friction>
            <bounce/>
            <contact/>
          </surface>
        </collision>
        <pose>0 0 0 0 0 0</pose>
        <enable_wind>false</enable_wind>
      </link>
      <link name='steering_wheel'>
        <pose>0.35773399999999977 -0.62786800000000031 0.98824299999999976 -1.3021010000000011 0 0</pose>
        <inertial>
          <mass>1</mass>
          <inertia>
            <ixx>0.14583299999999999</ixx>
            <ixy>0</ixy>
            <ixz>0</ixz>
            <iyy>0.14583299999999999</iyy>
            <iyz>0</iyz>
            <izz>0.125</izz>
          </inertia>
          <pose>0 0 0 0 0 0</pose>
        </inertial>
        <collision name='collision'>
          <geometry>
            <cylinder>
              <radius>0.178172</radius>
              <length>0.041845</length>
            </cylinder>
          </geometry>
          <surface>
            <contact>
              <ode>
                <min_depth>0.0030000000000000001</min_depth>
              </ode>
            </contact>
            <friction>
              <ode/>
            </friction>
            <bounce/>
          </surface>
        </collision>
        <visual name='visual'>
          <pose>0 0 0 1.302101 0 0</pose>
          <geometry>
            <mesh>
              <uri>model://prius hybrid/meshes/Hybrid.obj</uri>
              <scale>0.01 0.01 0.01</scale>
              <submesh>
                <name>Steering_Wheel</name>
                <center>true</center>
              </submesh>
            </mesh>
          </geometry>
        </visual>
        <enable_wind>false</enable_wind>
      </link>
      <link name='front_left_wheel'>
        <pose>0.75999999999999979 -1.4100000000000001 0.29999999999999999 0 0 0</pose>
        <inertial>
          <mass>11</mass>
          <inertia>
            <ixx>0.58631237999999997</ixx>
            <ixy>0</ixy>
            <iyy>0.33552910000000002</iyy>
            <ixz>0</ixz>
            <iyz>0</iyz>
            <izz>0.33552910000000002</izz>
          </inertia>
          <pose>0 0 0 0 0 0</pose>
        </inertial>
        <visual name='visual'>
          <pose>0.040000000000000001 0 0 0 0 0</pose>
          <geometry>
            <mesh>
              <uri>model://prius hybrid/meshes/Hybrid.obj</uri>
              <scale>0.01 0.01 0.01</scale>
              <submesh>
                <name>Wheel_Front_Left_</name>
                <center>true</center>
              </submesh>
            </mesh>
          </geometry>
        </visual>
        <collision name='collision'>
          <pose>0 0 0 0 1.5707963267948966 0</pose>
          <geometry>
            <sphere>
              <radius>0.31264999999999998</radius>
            </sphere>
          </geometry>
          <surface>
            <friction>
              <ode>
                <mu>0.90000000000000002</mu>
                <mu2>0.90000000000000002</mu2>
                <slip1>0</slip1>
                <slip2>0</slip2>
              </ode>
            </friction>
            <contact>
              <ode>
                <min_depth>0.001</min_depth>
                <kp>1000000000</kp>
              </ode>
            </contact>
            <bounce/>
          </surface>
        </collision>
        <enable_wind>false</enable_wind>
      </link>
      <link name='front_right_wheel'>
        <pose>-0.75999999999999979 -1.4100000000000001 0.29999999999999999 0 0 0</pose>
        <inertial>
          <mass>11</mass>
          <inertia>
            <ixx>0.58631237999999997</ixx>
            <ixy>0</ixy>
            <iyy>0.33552910000000002</iyy>
            <ixz>0</ixz>
            <iyz>0</iyz>
            <izz>0.33552910000000002</izz>
          </inertia>
          <pose>0 0 0 0 0 0</pose>
        </inertial>
        <visual name='visual'>
          <pose>-0.040000000000000001 0 0 0 0 0</pose>
          <pose>0 0 0 0 0 0</pose>
          <geometry>
            <mesh>
              <uri>model://prius hybrid/meshes/Hybrid.obj</uri>
              <scale>0.01 0.01 0.01</scale>
              <submesh>
                <name>Wheel_Front_Right</name>
                <center>true</center>
              </submesh>
            </mesh>
          </geometry>
        </visual>
        <collision name='collision'>
          <pose>0 0 0 0 1.5707963267948966 0</pose>
          <geometry>
            <sphere>
              <radius>0.31264999999999998</radius>
            </sphere>
          </geometry>
          <surface>
            <friction>
              <ode>
                <mu>0.90000000000000002</mu>
                <mu2>0.90000000000000002</mu2>
                <slip1>0</slip1>
                <slip2>0</slip2>
              </ode>
            </friction>
            <contact>
              <ode>
                <min_depth>0.001</min_depth>
                <kp>1000000000</kp>
              </ode>
            </contact>
            <bounce/>
          </surface>
        </collision>
        <enable_wind>false</enable_wind>
      </link>
      <link name='rear_left_wheel'>
        <pose>0.78599999999999959 1.4500000000000002 0.29999999999999999 0 0 0</pose>
        <inertial>
          <mass>11</mass>
          <inertia>
            <ixx>0.58631237999999997</ixx>
            <ixy>0</ixy>
            <iyy>0.33552910000000002</iyy>
            <ixz>0</ixz>
            <iyz>0</iyz>
            <izz>0.33552910000000002</izz>
          </inertia>
          <pose>0 0 0 0 0 0</pose>
        </inertial>
        <visual name='visual'>
          <pose>0.040000000000000001 0 0 0 0 0</pose>
          <geometry>
            <mesh>
              <uri>model://prius hybrid/meshes/Hybrid.obj</uri>
              <scale>0.01 0.01 0.01</scale>
              <submesh>
                <name>Wheel_Front_Left_</name>
                <center>true</center>
              </submesh>
            </mesh>
          </geometry>
        </visual>
        <collision name='collision'>
          <pose>0 0 0 0 1.5707963267948966 0</pose>
          <geometry>
            <sphere>
              <radius>0.31264999999999998</radius>
            </sphere>
          </geometry>
          <surface>
            <friction>
              <ode>
                <mu>1.1000000000000001</mu>
                <mu2>1.1000000000000001</mu2>
                <slip1>0</slip1>
                <slip2>0</slip2>
              </ode>
            </friction>
            <contact>
              <ode>
                <min_depth>0.001</min_depth>
                <kp>1000000000</kp>
              </ode>
            </contact>
            <bounce/>
          </surface>
        </collision>
        <enable_wind>false</enable_wind>
      </link>
      <link name='rear_right_wheel'>
        <pose>-0.78599999999999959 1.4500000000000002 0.29999999999999999 0 0 0</pose>
        <inertial>
          <mass>11</mass>
          <inertia>
            <ixx>0.58631237999999997</ixx>
            <ixy>0</ixy>
            <iyy>0.33552910000000002</iyy>
            <ixz>0</ixz>
            <iyz>0</iyz>
            <izz>0.33552910000000002</izz>
          </inertia>
          <pose>0 0 0 0 0 0</pose>
        </inertial>
        <visual name='visual'>
          <pose>-0.040000000000000001 0 0 0 0 0</pose>
          <geometry>
            <mesh>
              <uri>model://prius hybrid/meshes/Hybrid.obj</uri>
              <scale>0.01 0.01 0.01</scale>
              <submesh>
                <name>Wheel_Front_Right</name>
                <center>true</center>
              </submesh>
            </mesh>
          </geometry>
        </visual>
        <collision name='collision'>
          <pose>0 0 0 0 1.5707963267948966 0</pose>
          <geometry>
            <sphere>
              <radius>0.31264999999999998</radius>
            </sphere>
          </geometry>
          <surface>
            <friction>
              <ode>
                <mu>1.1000000000000001</mu>
                <mu2>1.1000000000000001</mu2>
                <slip1>0</slip1>
                <slip2>0</slip2>
              </ode>
            </friction>
            <contact>
              <ode>
                <min_depth>0.001</min_depth>
                <kp>1000000000</kp>
              </ode>
            </contact>
            <bounce/>
          </surface>
        </collision>
        <enable_wind>false</enable_wind>
      </link>
      <joint name='front_left_combined_joint' type='universal'>
        <pose>0 0 0 -0.087266462599716474 0 0</pose>
        <child>front_left_wheel</child>
        <parent>chassis</parent>
        <axis>
          <xyz>0 -2.775557561562891e-17 1</xyz>
          <limit>
            <lower>-0.87270000000000003</lower>
            <upper>0.87270000000000003</upper>
            <effort>inf</effort>
            <velocity>inf</velocity>
            <stiffness>100000000</stiffness>
            <dissipation>1</dissipation>
          </limit>
          <dynamics>
            <spring_reference>0</spring_reference>
            <spring_stiffness>0</spring_stiffness>
            <damping>0</damping>
            <friction>0</friction>
          </dynamics>
        </axis>
        <axis2>
          <xyz>1 0 0</xyz>
          <limit>
            <lower>-inf</lower>
            <upper>inf</upper>
            <effort>inf</effort>
            <velocity>inf</velocity>
            <stiffness>100000000</stiffness>
            <dissipation>1</dissipation>
          </limit>
          <dynamics>
            <spring_reference>0</spring_reference>
            <spring_stiffness>0</spring_stiffness>
            <damping>0</damping>
            <friction>18.047409225300001</friction>
          </dynamics>
        </axis2>
      </joint>
      <joint name='front_right_combined_joint' type='universal'>
        <pose>0 0 0 -0.087266462599716474 0 0</pose>
        <child>front_right_wheel</child>
        <parent>chassis</parent>
        <axis>
          <xyz>0 -2.775557561562891e-17 1</xyz>
          <limit>
            <lower>-0.87270000000000003</lower>
            <upper>0.87270000000000003</upper>
            <effort>inf</effort>
            <velocity>inf</velocity>
            <stiffness>100000000</stiffness>
            <dissipation>1</dissipation>
          </limit>
          <dynamics>
            <spring_reference>0</spring_reference>
            <spring_stiffness>0</spring_stiffness>
            <damping>0</damping>
            <friction>0</friction>
          </dynamics>
        </axis>
        <axis2>
          <xyz>1 0 0</xyz>
          <limit>
            <lower>-inf</lower>
            <upper>inf</upper>
            <effort>inf</effort>
            <velocity>inf</velocity>
            <stiffness>100000000</stiffness>
            <dissipation>1</dissipation>
          </limit>
          <dynamics>
            <spring_reference>0</spring_reference>
            <spring_stiffness>0</spring_stiffness>
            <damping>0</damping>
            <friction>18.047409225300001</friction>
          </dynamics>
        </axis2>
      </joint>
      <link name='rear_axle'>
        <pose>0 1.4500000000000002 0.29999999999999999 0 0 0</pose>
        <inertial>
          <mass>30</mass>
          <inertia>
            <ixx>0.084374999999999992</ixx>
            <ixy>0</ixy>
            <iyy>4.64581</iyy>
            <ixz>0</ixz>
            <iyz>0</iyz>
            <izz>4.64581</izz>
          </inertia>
          <pose>0 0 0 0 0 0</pose>
        </inertial>
        <visual name='visual'>
          <pose>0 0 0 0 1.5707963267948966 0</pose>
          <geometry>
            <cylinder>
              <length>1.357</length>
              <radius>0.074999999999999997</radius>
            </cylinder>
          </geometry>
          <material>
            <script>
              <name>Gazebo/Grey</name>
              <uri>file://media/materials/scripts/gazebo.material</uri>
            </script>
          </material>
        </visual>
        <enable_wind>false</enable_wind>
      </link>
      <joint name='rear_axle_joint' type='revolute'>
        <child>rear_axle</child>
        <parent>chassis</parent>
        <axis>
          <xyz>0 1 0</xyz>
          <limit>
            <lower>-0.050890585241730277</lower>
            <upper>0.050890585241730277</upper>
            <effort>inf</effort>
            <velocity>inf</velocity>
            <stiffness>100000000</stiffness>
            <dissipation>1</dissipation>
          </limit>
          <dynamics>
            <spring_reference>0</spring_reference>
            <spring_stiffness>20000</spring_stiffness>
            <damping>2000</damping>
            <friction>0</friction>
          </dynamics>
        </axis>
        <pose>0 0 0 0 0 0</pose>
      </joint>
      <joint name='rear_left_wheel_joint' type='revolute'>
        <child>rear_left_wheel</child>
        <parent>rear_axle</parent>
        <axis>
          <xyz>1 0 0</xyz>
          <limit>
            <lower>-inf</lower>
            <upper>inf</upper>
            <effort>inf</effort>
            <velocity>inf</velocity>
            <stiffness>100000000</stiffness>
            <dissipation>1</dissipation>
          </limit>
          <dynamics>
            <spring_reference>0</spring_reference>
            <spring_stiffness>0</spring_stiffness>
            <damping>0</damping>
            <friction>12.031606150200002</friction>
          </dynamics>
        </axis>
        <pose>0 0 0 0 0 0</pose>
      </joint>
      <joint name='rear_right_wheel_joint' type='revolute'>
        <child>rear_right_wheel</child>
        <parent>rear_axle</parent>
        <axis>
          <xyz>1 0 0</xyz>
          <limit>
            <lower>-inf</lower>
            <upper>inf</upper>
            <effort>inf</effort>
            <velocity>inf</velocity>
            <stiffness>100000000</stiffness>
            <dissipation>1</dissipation>
          </limit>
          <dynamics>
            <spring_reference>0</spring_reference>
            <spring_stiffness>0</spring_stiffness>
            <damping>0</damping>
            <friction>12.031606150200002</friction>
          </dynamics>
        </axis>
        <pose>0 0 0 0 0 0</pose>
      </joint>
      <joint name='steering_joint' type='revolute'>
        <pose>-0.0020000000000000573 0 -5.5511151231257827e-17 0 0 0</pose>
        <parent>chassis</parent>
        <child>steering_wheel</child>
        <axis>
          <xyz>0 -8.5372090472435325e-05 0.99999999635580317</xyz>
          <limit>
            <lower>-7.8499999999999996</lower>
            <upper>7.8499999999999996</upper>
            <effort>inf</effort>
            <velocity>inf</velocity>
            <stiffness>100000000</stiffness>
            <dissipation>1</dissipation>
          </limit>
          <dynamics>
            <spring_reference>0</spring_reference>
            <spring_stiffness>0</spring_stiffness>
            <damping>1</damping>
            <friction>0</friction>
          </dynamics>
        </axis>
        <physics>
          <ode>
            <cfm_damping>true</cfm_damping>
          </ode>
        </physics>
      </joint>
      <static>false</static>
      <self_collide>false</self_collide>
    </model>
    <model name='pedestrian_3_1_1'>
      <link name='link'>
        <inertial>
          <pose>0 -0.10000000000000001 0.94999999999999996 0 0 0</pose>
          <mass>80</mass>
          <inertia>
            <ixx>24.879999999999999</ixx>
            <ixy>0</ixy>
            <ixz>0</ixz>
            <iyy>25.73</iyy>
            <iyz>0</iyz>
            <izz>2.48</izz>
          </inertia>
        </inertial>
        <collision name='bottom'>
          <pose>0 -0.10000000000000001 0.01 0 0 0</pose>
          <geometry>
            <box>
              <size>0.5 0.34999999999999998 0.02</size>
            </box>
          </geometry>
          <surface>
            <friction>
              <ode/>
            </friction>
            <bounce/>
            <contact/>
          </surface>
        </collision>
        <collision name='person'>
          <pose>0 0 0.02 0.040000000000000001 0 0</pose>
          <geometry>
            <mesh>
              <uri>model://standing person/meshes/standing.dae</uri>
            </mesh>
          </geometry>
        </collision>
        <visual name='visual'>
          <pose>0 0 0.02 0.040000000000000001 0 0</pose>
          <geometry>
            <mesh>
              <uri>model://standing person/meshes/standing.dae</uri>
            </mesh>
          </geometry>
        </visual>
        <pose>0 0 0 0 0 0</pose>
        <enable_wind>false</enable_wind>
      </link>
      <pose>-0.58026675983709675 -6.4091045517509873 0 0 0 0</pose>
      <static>false</static>
      <self_collide>false</self_collide>
    </model>
    <light name='sun' type='directional'>
      <pose>0 0 10 0 0 0</pose>
      <cast_shadows>true</cast_shadows>
      <intensity>1</intensity>
      <direction>-0.5 0.10000000000000001 -0.90000000000000002</direction>
      <diffuse>0.800000012 0.800000012 0.800000012 1</diffuse>
      <specular>0.200000003 0.200000003 0.200000003 1</specular>
      <attenuation>
        <range>10</range>
        <linear>1</linear>
        <constant>1</constant>
        <quadratic>0</quadratic>
      </attenuation>
      <spot>
        <inner_angle>0</inner_angle>
        <outer_angle>0</outer_angle>
        <falloff>0</falloff>
      </spot>
    </light>
    <light name='spotlight' type='spot'>
      <pose>1.7660910037361708 3.5834723317409005 2 0 0 0</pose>
      <cast_shadows>true</cast_shadows>
      <intensity>1</intensity>
      <direction>0 0 -1</direction>
      <diffuse>0.5 0.5 0.5 1</diffuse>
      <specular>0.5 0.5 0.5 1</specular>
      <attenuation>
        <range>4</range>
        <linear>0.5</linear>
        <constant>0.20000000000000001</constant>
        <quadratic>0.01</quadratic>
      </attenuation>
      <spot>
        <inner_angle>0.10000000000000001</inner_angle>
        <outer_angle>0.5</outer_angle>
        <falloff>0.80000000000000004</falloff>
      </spot>
    </light>
  </world>
</sdf>
